package day09;

public class Exception03 {

	public static void main(String[] args) {
		/*
		 * 예외가 발생항면 발생한 시점부터 메서드 종료. (비정상종료)
		 * try~catch문을 활용하여 예외가 발생했을 때 프로그램이 비정상 종료되지 않고
		 * 이어서 정상적으로 종료될 수 있도록 처리하는 방법
		 * 예외발생 시점부터 실행은 안 됨. 
		 * 
		 * try{
		 * 예외가 발생할 수 있는 실행문;
		 * } catch(예외클래스명1 객체){
		 * 처리문;
		 * } catch(예외클래스명2 객체){
		 * 처리문;
		 * } catch(예외클래스명3 객체){
		 * 처리문;
		 * } finally // 잘 안 씀
		 * 
		 * */
		
		double res = 0;
		try {
//			res = 1/0; // 0으로 나눔.
			int arr[] = new int[5]; // 0~4번지
			arr[5]=10; // 5번지 없음.
		} catch (ArithmeticException e) {
			System.out.println("0으로 나누었습니다. 예외발생~!"); // 예외 발생하면 다음 catch는 실행되지 않음.
		} catch (IndexOutOfBoundsException e) {
			System.out.println("배열의 범위를 벗어났습니다. 예외발생~!");
		} catch (Exception e) { // 모든 예외의 조상
			System.out.println("Exception 발생!");
		}
		System.out.println("수고하셨습니다 :-)");
	}

}
